<sdf version='1.6'>
  <world name='default'>
    <model name='ground_plane'>
      <static>1</static>
      <link name='link'>
        <collision name='collision'>
          <geometry>
            <plane>
              <normal>0 0 1</normal>
              <size>100 100</size>
            </plane>
          </geometry>
          <surface>
            <contact>
              <collide_bitmask>65535</collide_bitmask>
              <ode/>
            </contact>
            <friction>
              <ode>
                <mu>100</mu>
                <mu2>50</mu2>
              </ode>
              <torsional>
                <ode/>
              </torsional>
            </friction>
            <bounce/>
          </surface>
          <max_contacts>10</max_contacts>
        </collision>
        <visual name='visual'>
          <cast_shadows>0</cast_shadows>
          <geometry>
            <plane>
              <normal>0 0 1</normal>
              <size>100 100</size>
            </plane>
          </geometry>
          <material>
            <script>
              <uri>file://media/materials/scripts/gazebo.material</uri>
              <name>Gazebo/Grey</name>
            </script>
          </material>
        </visual>
        <self_collide>0</self_collide>
        <enable_wind>0</enable_wind>
        <kinematic>0</kinematic>
      </link>
      <pose frame=''>0 0 -0.005 0 -0 0</pose>
    </model>
    <model name='fetchit_arena1'>
      <static>1</static>
      <link name='link'>
        <visual name='visual'>
          <geometry>
            <mesh>
              <uri>model://fetchit_arena/meshes/fetchit_arena1.dae</uri>
              <scale>1 1 1</scale>
            </mesh>
          </geometry>
        </visual>
        <collision name='collision'>
          <geometry>
            <mesh>
              <uri>model://fetchit_arena/meshes/fetchit_arena1.dae</uri>
              <scale>1 1 1</scale>
            </mesh>
          </geometry>
          <surface>
            <friction>
              <ode>
                <mu>30</mu>
                <mu2>30</mu2>
              </ode>
              <torsional>
                <ode/>
              </torsional>
            </friction>
            <contact>
              <ode>
                <soft_cfm>0</soft_cfm>
                <soft_erp>0.2</soft_erp>
                <kp>1e+13</kp>
                <kd>1</kd>
                <max_vel>0.01</max_vel>
                <min_depth>0</min_depth>
              </ode>
            </contact>
            <bounce/>
          </surface>
          <max_contacts>10</max_contacts>
        </collision>
        <velocity_decay>
          <linear>0</linear>
          <angular>0</angular>
        </velocity_decay>
        <self_collide>0</self_collide>
        <kinematic>0</kinematic>
        <gravity>1</gravity>
        <enable_wind>0</enable_wind>
      </link>
      <pose frame=''>0 0 0 0 -0 0</pose>
    </model>
    <model name='fetchit_table_sick1'>
      <static>1</static>
      <link name='link'>
        <inertial>
          <mass>0.0592855</mass>
          <inertia>
            <ixx>2.31818e-05</ixx>
            <ixy>0</ixy>
            <ixz>0</ixz>
            <iyy>2.31852e-05</iyy>
            <iyz>0</iyz>
            <izz>8.88945e-06</izz>
          </inertia>
        </inertial>
        <collision name='collision'>
          <geometry>
            <mesh>
              <uri>model://fetchit_table_sick/meshes/simple_table.stl</uri>
              <scale>1 1 1</scale>
            </mesh>
          </geometry>
          <surface>
            <friction>
              <ode>
                <mu>30</mu>
                <mu2>30</mu2>
              </ode>
              <torsional>
                <ode/>
              </torsional>
            </friction>
            <contact>
              <ode/>
            </contact>
            <bounce/>
          </surface>
          <max_contacts>10</max_contacts>
        </collision>
        <visual name='visual'>
          <geometry>
            <mesh>
              <uri>model://fetchit_table_sick/meshes/table_sick.dae</uri>
              <scale>1 1 1</scale>
            </mesh>
          </geometry>
        </visual>
        <velocity_decay>
          <linear>0</linear>
          <angular>0</angular>
        </velocity_decay>
        <self_collide>0</self_collide>
        <kinematic>0</kinematic>
        <gravity>1</gravity>
        <enable_wind>0</enable_wind>
      </link>
      <pose frame=''>-0.305 1.28179 0 0 -0 0</pose>
    </model>
    <model name='gearbox_bottom_grey2'>
      <static>0</static>
      <link name='link'>
        <inertial>
          <pose frame=''>0 0 0.026185 0 -0 0</pose>
          <mass>0.370561</mass>
          <inertia>
            <ixx>0.000131217</ixx>
            <ixy>0</ixy>
            <ixz>0</ixz>
            <iyy>0.000981018</iyy>
            <iyz>0</iyz>
            <izz>0.000942848</izz>
          </inertia>
        </inertial>
        <collision name='collision'>
          <geometry>
            <mesh>
              <uri>model://gearbox_bottom_grey/meshes/gearbox_bottom_simple.stl</uri>
              <scale>1 1 1</scale>
            </mesh>
          </geometry>
          <surface>
            <friction>
              <ode>
                <mu>30</mu>
                <mu2>30</mu2>
              </ode>
              <torsional>
                <ode/>
              </torsional>
            </friction>
            <contact>
              <ode/>
            </contact>
            <bounce/>
          </surface>
          <max_contacts>10</max_contacts>
        </collision>
        <visual name='visual'>
          <geometry>
            <mesh>
              <uri>model://gearbox_bottom_grey/meshes/gearBoxBottom_grey.dae</uri>
              <scale>1 1 1</scale>
            </mesh>
          </geometry>
        </visual>
        <velocity_decay>
          <linear>0</linear>
          <angular>0</angular>
        </velocity_decay>
        <self_collide>0</self_collide>
        <kinematic>0</kinematic>
        <gravity>1</gravity>
        <enable_wind>0</enable_wind>
      </link>
      <pose frame=''>0.070919 1.34706 0.804964 -1.5708 -0 2.31728</pose>
    </model>
    <model name='gearbox_top_grey1'>
      <static>0</static>
      <link name='link'>
        <inertial>
          <pose frame=''>0 0 0 0 -0 0</pose>
          <mass>0.228259</mass>
          <inertia>
            <ixx>4.84526e-05</ixx>
            <ixy>0</ixy>
            <ixz>0</ixz>
            <iyy>0.000571913</iyy>
            <iyz>0</iyz>
            <izz>0.000580777</izz>
          </inertia>
        </inertial>
        <collision name='collision'>
          <geometry>
            <mesh>
              <uri>model://gearbox_top_grey/meshes/gearBoxTop_v3.stl</uri>
              <scale>1 1 1</scale>
            </mesh>
          </geometry>
          <surface>
            <friction>
              <ode>
                <mu>30</mu>
                <mu2>30</mu2>
              </ode>
              <torsional>
                <ode/>
              </torsional>
            </friction>
            <contact>
              <ode/>
            </contact>
            <bounce/>
          </surface>
          <max_contacts>10</max_contacts>
        </collision>
        <visual name='visual'>
          <geometry>
            <mesh>
              <uri>model://gearbox_top_grey/meshes/gearBoxTop_grey.dae</uri>
              <scale>1 1 1</scale>
            </mesh>
          </geometry>
        </visual>
        <velocity_decay>
          <linear>0</linear>
          <angular>0</angular>
        </velocity_decay>
        <self_collide>0</self_collide>
        <kinematic>0</kinematic>
        <gravity>1</gravity>
        <enable_wind>0</enable_wind>
      </link>
      <pose frame=''>-0.64672 1.3319 0.801285 1e-06 0.173592 1.29027</pose>
    </model>
    <light name='user_point_light_0' type='point'>
      <pose frame=''>1 1 3.5 0 -0 0</pose>
      <diffuse>0.7 0.7 0.7 1</diffuse>
      <specular>0.1 0.1 0.1 1</specular>
      <attenuation>
        <range>10</range>
        <constant>0.5</constant>
        <linear>0.01</linear>
        <quadratic>0.001</quadratic>
      </attenuation>
      <cast_shadows>0</cast_shadows>
      <direction>0 0 -1</direction>
    </light>
    <light name='user_point_light_1' type='point'>
      <pose frame=''>-1 1 3.5 0 -0 0</pose>
      <diffuse>0.7 0.7 0.7 1</diffuse>
      <specular>0.1 0.1 0.1 1</specular>
      <attenuation>
        <range>10</range>
        <constant>0.5</constant>
        <linear>0.01</linear>
        <quadratic>0.001</quadratic>
      </attenuation>
      <cast_shadows>0</cast_shadows>
      <direction>0 0 -1</direction>
    </light>
    <light name='user_point_light_2' type='point'>
      <pose frame=''>-1 -1 3.5 0 -0 0</pose>
      <diffuse>0.7 0.7 0.7 1</diffuse>
      <specular>0.1 0.1 0.1 1</specular>
      <attenuation>
        <range>10</range>
        <constant>0.5</constant>
        <linear>0.01</linear>
        <quadratic>0.001</quadratic>
      </attenuation>
      <cast_shadows>0</cast_shadows>
      <direction>0 0 -1</direction>
    </light>
    <light name='user_point_light_3' type='point'>
      <pose frame=''>1 -1 3.5 0 -0 0</pose>
      <diffuse>0.7 0.7 0.7 1</diffuse>
      <specular>0.1 0.1 0.1 1</specular>
      <attenuation>
        <range>10</range>
        <constant>0.5</constant>
        <linear>0.01</linear>
        <quadratic>0.001</quadratic>
      </attenuation>
      <cast_shadows>0</cast_shadows>
      <direction>0 0 -1</direction>
    </light>
    <gravity>0 0 -9.8</gravity>
    <magnetic_field>6e-06 2.3e-05 -4.2e-05</magnetic_field>
    <atmosphere type='adiabatic'/>
    <physics name='default_physics' default='0' type='ode'>
      <max_step_size>0.001</max_step_size>
      <real_time_factor>1</real_time_factor>
      <real_time_update_rate>1000</real_time_update_rate>
    </physics>
    <scene>
      <ambient>0.4 0.4 0.4 1</ambient>
      <background>0.7 0.7 0.7 1</background>
      <shadows>1</shadows>
    </scene>
    <audio>
      <device>default</device>
    </audio>
    <wind/>
    <spherical_coordinates>
      <surface_model>EARTH_WGS84</surface_model>
      <latitude_deg>0</latitude_deg>
      <longitude_deg>0</longitude_deg>
      <elevation>0</elevation>
      <heading_deg>0</heading_deg>
    </spherical_coordinates>
    <model name='fetch'>
      <link name='base_link'>
        <pose frame=''>0 0 0 0 -0 0</pose>
        <inertial>
          <pose frame=''>-0.028327 0.000912 0.103535 0 -0 0</pose>
          <mass>83.4572</mass>
          <inertia>
            <ixx>10.2084</ixx>
            <ixy>0.0213394</ixy>
            <ixz>1.10946</ixz>
            <iyy>10.4919</iyy>
            <iyz>-0.0326219</iyz>
            <izz>5.3614</izz>
          </inertia>
        </inertial>
        <collision name='base_link_collision'>
          <pose frame=''>0 0 0 0 -0 0</pose>
          <geometry>
            <mesh>
              <scale>1 1 1</scale>
              <uri>/home/Jeremy/catkin_ws/src/fetch_ros/fetch_description/meshes/base_link_collision.STL</uri>
            </mesh>
          </geometry>
          <surface>
            <contact>
              <ode>
                <kp>1e+08</kp>
                <kd>10</kd>
                <max_vel>10</max_vel>
                <min_depth>0.0005</min_depth>
              </ode>
            </contact>
            <friction>
              <ode>
                <mu>0.1</mu>
                <mu2>0.1</mu2>
                <fdir1>1 0 0</fdir1>
              </ode>
              <torsional>
                <ode/>
              </torsional>
            </friction>
            <bounce/>
          </surface>
          <max_contacts>10</max_contacts>
        </collision>
        <collision name='base_link_fixed_joint_lump__bl_caster_link_collision_1'>
          <pose frame=''>-0.2 -0.12 0.055325 0 -0 0</pose>
          <geometry>
            <sphere>
              <radius>0.0601</radius>
            </sphere>
          </geometry>
          <surface>
            <contact>
              <ode>
                <kp>1e+08</kp>
                <kd>10</kd>
                <max_vel>10</max_vel>
                <min_depth>0.001</min_depth>
              </ode>
            </contact>
            <friction>
              <ode>
                <mu>0.1</mu>
                <mu2>0.1</mu2>
              </ode>
              <torsional>
                <ode/>
              </torsional>
            </friction>
            <bounce/>
          </surface>
          <max_contacts>10</max_contacts>
        </collision>
        <collision name='base_link_fixed_joint_lump__br_caster_link_collision_2'>
          <pose frame=''>-0.2 0.12 0.055325 0 -0 0</pose>
          <geometry>
            <sphere>
              <radius>0.0601</radius>
            </sphere>
          </geometry>
          <surface>
            <contact>
              <ode>
                <kp>1e+08</kp>
                <kd>10</kd>
                <max_vel>10</max_vel>
                <min_depth>0.001</min_depth>
              </ode>
            </contact>
            <friction>
              <ode>
                <mu>0.1</mu>
                <mu2>0.1</mu2>
              </ode>
              <torsional>
                <ode/>
              </torsional>
            </friction>
            <bounce/>
          </surface>
          <max_contacts>10</max_contacts>
        </collision>
        <collision name='base_link_fixed_joint_lump__estop_link_collision_3'>
          <pose frame=''>-0.12465 0.23892 0.31127 1.5708 -0 0</pose>
          <geometry>
            <mesh>
              <scale>1 1 1</scale>
              <uri>/home/Jeremy/catkin_ws/src/fetch_ros/fetch_description/meshes/estop_link.STL</uri>
            </mesh>
          </geometry>
          <surface>
            <contact>
              <ode/>
            </contact>
            <friction>
              <ode/>
              <torsional>
                <ode/>
              </torsional>
            </friction>
            <bounce/>
          </surface>
          <max_contacts>10</max_contacts>
        </collision>
        <collision name='base_link_fixed_joint_lump__fl_caster_link_collision_4'>
          <pose frame=''>0.15 0.12 0.055325 0 -0 0</pose>
          <geometry>
            <sphere>
              <radius>0.0601</radius>
            </sphere>
          </geometry>
          <surface>
            <contact>
              <ode>
                <kp>1e+08</kp>
                <kd>10</kd>
                <max_vel>10</max_vel>
                <min_depth>0.001</min_depth>
              </ode>
            </contact>
            <friction>
              <ode>
                <mu>0.1</mu>
                <mu2>0.1</mu2>
              </ode>
              <torsional>
                <ode/>
              </torsional>
            </friction>
            <bounce/>
          </surface>
          <max_contacts>10</max_contacts>
        </collision>
        <collision name='base_link_fixed_joint_lump__fr_caster_link_collision_5'>
          <pose frame=''>0.15 -0.12 0.055325 0 -0 0</pose>
          <geometry>
            <sphere>
              <radius>0.0601</radius>
            </sphere>
          </geometry>
          <surface>
            <contact>
              <ode>
                <kp>1e+08</kp>
                <kd>10</kd>
                <max_vel>10</max_vel>
                <min_depth>0.001</min_depth>
              </ode>
            </contact>
            <friction>
              <ode>
                <mu>0.1</mu>
                <mu2>0.1</mu2>
              </ode>
              <torsional>
                <ode/>
              </torsional>
            </friction>
            <bounce/>
          </surface>
          <max_contacts>10</max_contacts>
        </collision>
        <collision name='base_link_fixed_joint_lump__laser_link_collision_6'>
          <pose frame=''>0.235 0 0.2878 -3.14159 -0 0</pose>
          <geometry>
            <mesh>
              <scale>1 1 1</scale>
              <uri>/home/Jeremy/catkin_ws/src/fetch_ros/fetch_description/meshes/laser_link.STL</uri>
            </mesh>
          </geometry>
          <surface>
            <contact>
              <ode/>
            </contact>
            <friction>
              <ode/>
              <torsional>
                <ode/>
              </torsional>
            </friction>
            <bounce/>
          </surface>
          <max_contacts>10</max_contacts>
        </collision>
        <collision name='base_link_fixed_joint_lump__torso_fixed_link_collision_7'>
          <pose frame=''>-0.086875 0 0.377425 0 -0 0</pose>
          <geometry>
            <mesh>
              <scale>1 1 1</scale>
              <uri>/home/Jeremy/catkin_ws/src/fetch_ros/fetch_description/meshes/torso_fixed_link.STL</uri>
            </mesh>
          </geometry>
          <max_contacts>10</max_contacts>
          <surface>
            <contact>
              <ode/>
            </contact>
            <bounce/>
            <friction>
              <torsional>
                <ode/>
              </torsional>
              <ode/>
            </friction>
          </surface>
        </collision>
        <visual name='base_link_visual'>
          <pose frame=''>0 0 0 0 -0 0</pose>
          <geometry>
            <mesh>
              <scale>1 1 1</scale>
              <uri>/home/Jeremy/catkin_ws/src/fetch_ros/fetch_description/meshes/base_link.dae</uri>
            </mesh>
          </geometry>
          <material>
            <script>
              <uri>__default__</uri>
              <name>__default__</name>
            </script>
          </material>
        </visual>
        <visual name='base_link_fixed_joint_lump__bl_caster_link_visual_1'>
          <pose frame=''>-0.2 -0.12 0.055325 0 -0 0</pose>
          <geometry>
            <sphere>
              <radius>0.0601</radius>
            </sphere>
          </geometry>
          <material>
            <script>
              <uri>__default__</uri>
              <name>__default__</name>
            </script>
          </material>
        </visual>
        <visual name='base_link_fixed_joint_lump__br_caster_link_visual_2'>
          <pose frame=''>-0.2 0.12 0.055325 0 -0 0</pose>
          <geometry>
            <sphere>
              <radius>0.0601</radius>
            </sphere>
          </geometry>
          <material>
            <script>
              <uri>__default__</uri>
              <name>__default__</name>
            </script>
          </material>
        </visual>
        <visual name='base_link_fixed_joint_lump__estop_link_visual_3'>
          <pose frame=''>-0.12465 0.23892 0.31127 1.5708 -0 0</pose>
          <geometry>
            <mesh>
              <scale>1 1 1</scale>
              <uri>/home/Jeremy/catkin_ws/src/fetch_ros/fetch_description/meshes/estop_link.dae</uri>
            </mesh>
          </geometry>
          <material>
            <script>
              <name>Gazebo/Red</name>
              <uri>file://media/materials/scripts/gazebo.material</uri>
            </script>
          </material>
        </visual>
        <visual name='base_link_fixed_joint_lump__fl_caster_link_visual_4'>
          <pose frame=''>0.15 0.12 0.055325 0 -0 0</pose>
          <geometry>
            <sphere>
              <radius>0.0601</radius>
            </sphere>
          </geometry>
          <material>
            <script>
              <uri>__default__</uri>
              <name>__default__</name>
            </script>
          </material>
        </visual>
        <visual name='base_link_fixed_joint_lump__fr_caster_link_visual_5'>
          <pose frame=''>0.15 -0.12 0.055325 0 -0 0</pose>
          <geometry>
            <sphere>
              <radius>0.0601</radius>
            </sphere>
          </geometry>
          <material>
            <script>
              <uri>__default__</uri>
              <name>__default__</name>
            </script>
          </material>
        </visual>
        <visual name='base_link_fixed_joint_lump__laser_link_visual_6'>
          <pose frame=''>0.235 0 0.2878 -3.14159 -0 0</pose>
          <geometry>
            <mesh>
              <scale>1 1 1</scale>
              <uri>/home/Jeremy/catkin_ws/src/fetch_ros/fetch_description/meshes/laser_link.STL</uri>
            </mesh>
          </geometry>
          <material>
            <script>
              <uri>__default__</uri>
              <name>__default__</name>
            </script>
          </material>
        </visual>
        <visual name='base_link_fixed_joint_lump__torso_fixed_link_visual_7'>
          <pose frame=''>-0.086875 0 0.377425 0 -0 0</pose>
          <geometry>
            <mesh>
              <scale>1 1 1</scale>
              <uri>/home/Jeremy/catkin_ws/src/fetch_ros/fetch_description/meshes/torso_fixed_link.dae</uri>
            </mesh>
          </geometry>
        </visual>
        <velocity_decay/>
        <velocity_decay/>
        <velocity_decay/>
        <velocity_decay/>
        <velocity_decay/>
        <velocity_decay/>
        <gravity>1</gravity>
        <velocity_decay/>
        <sensor name='base_laser' type='ray'>
          <visualize>0</visualize>
          <update_rate>15</update_rate>
          <ray>
            <scan>
              <horizontal>
                <samples>662</samples>
                <resolution>1</resolution>
                <min_angle>-1.91986</min_angle>
                <max_angle>1.91986</max_angle>
              </horizontal>
              <vertical>
                <samples>1</samples>
                <min_angle>0</min_angle>
                <max_angle>0</max_angle>
              </vertical>
            </scan>
            <range>
              <min>0.05</min>
              <max>25</max>
              <resolution>0.01</resolution>
            </range>
            <noise>
              <type>gaussian</type>
              <mean>0</mean>
              <stddev>0.02</stddev>
            </noise>
          </ray>
          <plugin name='gazebo_ros_base_hokuyo_controller' filename='libgazebo_ros_laser.so'>
            <topicName>/base_scan</topicName>
            <frameName>laser_link</frameName>
            <robotNamespace>/</robotNamespace>
          </plugin>
          <pose frame=''>0.235 0 0.2878 -3.14159 -0 0</pose>
        </sensor>
        <self_collide>0</self_collide>
        <enable_wind>0</enable_wind>
        <kinematic>0</kinematic>
      </link>
      <link name='l_wheel_link'>
        <pose frame=''>0.001291 0.18738 0.055325 0 -0 0</pose>
        <inertial>
          <pose frame=''>0 0 0 0 -0 0</pose>
          <mass>4.3542</mass>
          <inertia>
            <ixx>0.0045</ixx>
            <ixy>0</ixy>
            <ixz>0</ixz>
            <iyy>0.005</iyy>
            <iyz>0</iyz>
            <izz>0.0045</izz>
          </inertia>
        </inertial>
        <collision name='l_wheel_link_collision'>
          <pose frame=''>0 0 0 0 -0 0</pose>
          <geometry>
            <mesh>
              <scale>1 1 1</scale>
              <uri>/home/Jeremy/catkin_ws/src/fetch_ros/fetch_description/meshes/l_wheel_link_collision.STL</uri>
            </mesh>
          </geometry>
          <surface>
            <contact>
              <ode>
                <kp>1e+06</kp>
                <kd>100</kd>
                <max_vel>1</max_vel>
                <min_depth>0.01</min_depth>
              </ode>
            </contact>
            <friction>
              <ode>
                <mu>1e+14</mu>
                <mu2>1e+14</mu2>
              </ode>
              <torsional>
                <ode/>
              </torsional>
            </friction>
            <bounce/>
          </surface>
          <max_contacts>10</max_contacts>
        </collision>
        <visual name='l_wheel_link_visual'>
          <pose frame=''>0 0 0 0 -0 0</pose>
          <geometry>
            <mesh>
              <scale>1 1 1</scale>
              <uri>/home/Jeremy/catkin_ws/src/fetch_ros/fetch_description/meshes/l_wheel_link.STL</uri>
            </mesh>
          </geometry>
          <material>
            <script>
              <name>Gazebo/Black</name>
              <uri>file://media/materials/scripts/gazebo.material</uri>
            </script>
          </material>
        </visual>
        <gravity>1</gravity>
        <velocity_decay/>
        <self_collide>0</self_collide>
        <enable_wind>0</enable_wind>
        <kinematic>0</kinematic>
      </link>
      <joint name='l_wheel_joint' type='revolute'>
        <child>l_wheel_link</child>
        <parent>base_link</parent>
        <axis>
          <xyz>0 1 -0</xyz>
          <limit>
            <lower>-1e+16</lower>
            <upper>1e+16</upper>
          </limit>
          <dynamics>
            <spring_reference>0</spring_reference>
            <spring_stiffness>0</spring_stiffness>
          </dynamics>
          <use_parent_model_frame>1</use_parent_model_frame>
        </axis>
        <physics>
          <ode>
            <implicit_spring_damper>1</implicit_spring_damper>
            <cfm_damping>1</cfm_damping>
            <limit>
              <cfm>0</cfm>
              <erp>0.2</erp>
            </limit>
          </ode>
        </physics>
      </joint>
      <link name='r_wheel_link'>
        <pose frame=''>0.001291 -0.18738 0.055325 0 -0 0</pose>
        <inertial>
          <pose frame=''>0 0 0 0 -0 0</pose>
          <mass>4.3542</mass>
          <inertia>
            <ixx>0.0045</ixx>
            <ixy>0</ixy>
            <ixz>0</ixz>
            <iyy>0.005</iyy>
            <iyz>0</iyz>
            <izz>0.0045</izz>
          </inertia>
        </inertial>
        <collision name='r_wheel_link_collision'>
          <pose frame=''>0 0 0 0 -0 0</pose>
          <geometry>
            <mesh>
              <scale>1 1 1</scale>
              <uri>/home/Jeremy/catkin_ws/src/fetch_ros/fetch_description/meshes/r_wheel_link_collision.STL</uri>
            </mesh>
          </geometry>
          <surface>
            <contact>
              <ode>
                <kp>1e+06</kp>
                <kd>100</kd>
                <max_vel>1</max_vel>
                <min_depth>0.01</min_depth>
              </ode>
            </contact>
            <friction>
              <ode>
                <mu>1e+14</mu>
                <mu2>1e+14</mu2>
              </ode>
              <torsional>
                <ode/>
              </torsional>
            </friction>
            <bounce/>
          </surface>
          <max_contacts>10</max_contacts>
        </collision>
        <visual name='r_wheel_link_visual'>
          <pose frame=''>0 0 0 0 -0 0</pose>
          <geometry>
            <mesh>
              <scale>1 1 1</scale>
              <uri>/home/Jeremy/catkin_ws/src/fetch_ros/fetch_description/meshes/r_wheel_link.STL</uri>
            </mesh>
          </geometry>
          <material>
            <script>
              <name>Gazebo/Black</name>
              <uri>file://media/materials/scripts/gazebo.material</uri>
            </script>
          </material>
        </visual>
        <gravity>1</gravity>
        <velocity_decay/>
        <self_collide>0</self_collide>
        <enable_wind>0</enable_wind>
        <kinematic>0</kinematic>
      </link>
      <joint name='r_wheel_joint' type='revolute'>
        <child>r_wheel_link</child>
        <parent>base_link</parent>
        <axis>
          <xyz>0 1 -0</xyz>
          <limit>
            <lower>-1e+16</lower>
            <upper>1e+16</upper>
          </limit>
          <dynamics>
            <spring_reference>0</spring_reference>
            <spring_stiffness>0</spring_stiffness>
          </dynamics>
          <use_parent_model_frame>1</use_parent_model_frame>
        </axis>
        <physics>
          <ode>
            <implicit_spring_damper>1</implicit_spring_damper>
            <cfm_damping>1</cfm_damping>
            <limit>
              <cfm>0</cfm>
              <erp>0.2</erp>
            </limit>
          </ode>
        </physics>
      </joint>
      <link name='torso_lift_link'>
        <pose frame=''>-0.086875 0 0.37743 0 -0 0</pose>
        <inertial>
          <pose frame=''>-0.000984 -0.000886 0.286874 0 -0 0</pose>
          <mass>10.949</mass>
          <inertia>
            <ixx>0.36931</ixx>
            <ixy>-3.0664e-06</ixy>
            <ixz>-0.0147406</ixz>
            <iyy>0.367812</iyy>
            <iyz>-0.000535712</iyz>
            <izz>0.0971639</izz>
          </inertia>
        </inertial>
        <collision name='torso_lift_link_collision'>
          <pose frame=''>0 0 0 0 -0 0</pose>
          <geometry>
            <mesh>
              <scale>1 1 1</scale>
              <uri>/home/Jeremy/catkin_ws/src/fetch_ros/fetch_description/meshes/torso_lift_link_collision.STL</uri>
            </mesh>
          </geometry>
          <max_contacts>10</max_contacts>
          <surface>
            <contact>
              <ode/>
            </contact>
            <bounce/>
            <friction>
              <torsional>
                <ode/>
              </torsional>
              <ode/>
            </friction>
          </surface>
        </collision>
        <collision name='torso_lift_link_fixed_joint_lump__bellows_link2_collision_1'>
          <pose frame=''>0 0 0 0 -0 0</pose>
          <geometry>
            <mesh>
              <scale>1 1 1</scale>
              <uri>/home/Jeremy/catkin_ws/src/fetch_ros/fetch_description/meshes/bellows_link_collision.STL</uri>
            </mesh>
          </geometry>
          <surface>
            <contact>
              <ode/>
            </contact>
            <friction>
              <ode/>
              <torsional>
                <ode/>
              </torsional>
            </friction>
            <bounce/>
          </surface>
          <max_contacts>10</max_contacts>
        </collision>
        <visual name='torso_lift_link_visual'>
          <pose frame=''>0 0 0 0 -0 0</pose>
          <geometry>
            <mesh>
              <scale>1 1 1</scale>
              <uri>/home/Jeremy/catkin_ws/src/fetch_ros/fetch_description/meshes/torso_lift_link.dae</uri>
            </mesh>
          </geometry>
        </visual>
        <visual name='torso_lift_link_fixed_joint_lump__bellows_link2_visual_1'>
          <pose frame=''>0 0 0 0 -0 0</pose>
          <geometry>
            <mesh>
              <scale>1 1 1</scale>
              <uri>/home/Jeremy/catkin_ws/src/fetch_ros/fetch_description/meshes/bellows_link.STL</uri>
            </mesh>
          </geometry>
          <material>
            <script>
              <name>Gazebo/Black</name>
              <uri>file://media/materials/scripts/gazebo.material</uri>
            </script>
          </material>
        </visual>
        <gravity>1</gravity>
        <velocity_decay/>
        <self_collide>0</self_collide>
        <enable_wind>0</enable_wind>
        <kinematic>0</kinematic>
      </link>
      <joint name='torso_lift_joint' type='prismatic'>
        <child>torso_lift_link</child>
        <parent>base_link</parent>
        <axis>
          <xyz>0 0 1</xyz>
          <limit>
            <lower>0</lower>
            <upper>0.38615</upper>
            <effort>450</effort>
            <velocity>0.1</velocity>
          </limit>
          <dynamics>
            <damping>100</damping>
            <friction>0</friction>
            <spring_reference>0</spring_reference>
            <spring_stiffness>0</spring_stiffness>
          </dynamics>
          <use_parent_model_frame>1</use_parent_model_frame>
        </axis>
      </joint>
      <link name='bellows_link'>
        <pose frame=''>-0.086875 0 0.37743 0 -0 0</pose>
        <inertial>
          <pose frame=''>0.019132 -0 -0.134862 0 -0 0</pose>
          <mass>0.169374</mass>
          <inertia>
            <ixx>0.00331159</ixx>
            <ixy>-8.9231e-18</ixy>
            <ixz>-5.38622e-08</ixz>
            <iyy>0.00174447</iyy>
            <iyz>-8.06965e-17</iyz>
            <izz>0.00169418</izz>
          </inertia>
        </inertial>
        <collision name='bellows_link_collision'>
          <pose frame=''>0 0 0 0 -0 0</pose>
          <geometry>
            <mesh>
              <scale>1 1 1</scale>
              <uri>/home/Jeremy/catkin_ws/src/fetch_ros/fetch_description/meshes/bellows_link_collision.STL</uri>
            </mesh>
          </geometry>
          <surface>
            <contact>
              <ode/>
            </contact>
            <friction>
              <ode/>
              <torsional>
                <ode/>
              </torsional>
            </friction>
            <bounce/>
          </surface>
          <max_contacts>10</max_contacts>
        </collision>
        <visual name='bellows_link_visual'>
          <pose frame=''>0 0 0 0 -0 0</pose>
          <geometry>
            <mesh>
              <scale>1 1 1</scale>
              <uri>/home/Jeremy/catkin_ws/src/fetch_ros/fetch_description/meshes/bellows_link.STL</uri>
            </mesh>
          </geometry>
          <material>
            <script>
              <name>Gazebo/Black</name>
              <uri>file://media/materials/scripts/gazebo.material</uri>
            </script>
          </material>
        </visual>
        <gravity>1</gravity>
        <velocity_decay/>
        <self_collide>0</self_collide>
        <enable_wind>0</enable_wind>
        <kinematic>0</kinematic>
      </link>
      <joint name='bellows_joint' type='prismatic'>
        <child>bellows_link</child>
        <parent>torso_lift_link</parent>
        <axis>
          <xyz>0 -0 -1</xyz>
          <limit>
            <lower>0</lower>
            <upper>0.4</upper>
            <effort>5</effort>
            <velocity>0.1</velocity>
          </limit>
          <dynamics>
            <spring_reference>0</spring_reference>
            <spring_stiffness>0</spring_stiffness>
          </dynamics>
          <use_parent_model_frame>1</use_parent_model_frame>
        </axis>
      </joint>
      <link name='head_pan_link'>
        <pose frame=''>-0.03375 0 0.980431 0 -0 0</pose>
        <inertial>
          <pose frame=''>0.0321 0.0161 0.039 0 -0 0</pose>
          <mass>2.2556</mass>
          <inertia>
            <ixx>0.0129</ixx>
            <ixy>0.0002</ixy>
            <ixz>0.0007</ixz>
            <iyy>0.0095</iyy>
            <iyz>-0</iyz>
            <izz>0.0184</izz>
          </inertia>
        </inertial>
        <collision name='head_pan_link_collision'>
          <pose frame=''>0 0 0 0 -0 0</pose>
          <geometry>
            <mesh>
              <scale>1 1 1</scale>
              <uri>/home/Jeremy/catkin_ws/src/fetch_ros/fetch_description/meshes/head_pan_link_collision.STL</uri>
            </mesh>
          </geometry>
          <max_contacts>10</max_contacts>
          <surface>
            <contact>
              <ode/>
            </contact>
            <bounce/>
            <friction>
              <torsional>
                <ode/>
              </torsional>
              <ode/>
            </friction>
          </surface>
        </collision>
        <visual name='head_pan_link_visual'>
          <pose frame=''>0 0 0 0 -0 0</pose>
          <geometry>
            <mesh>
              <scale>1 1 1</scale>
              <uri>/home/Jeremy/catkin_ws/src/fetch_ros/fetch_description/meshes/head_pan_link.dae</uri>
            </mesh>
          </geometry>
        </visual>
        <self_collide>0</self_collide>
        <enable_wind>0</enable_wind>
        <kinematic>0</kinematic>
      </link>
      <joint name='head_pan_joint' type='revolute'>
        <child>head_pan_link</child>
        <parent>torso_lift_link</parent>
        <axis>
          <xyz>0 0 1</xyz>
          <limit>
            <lower>-1.57</lower>
            <upper>1.57</upper>
            <effort>0.32</effort>
            <velocity>1.57</velocity>
          </limit>
          <dynamics>
            <spring_reference>0</spring_reference>
            <spring_stiffness>0</spring_stiffness>
          </dynamics>
          <use_parent_model_frame>1</use_parent_model_frame>
        </axis>
      </joint>
      <link name='head_tilt_link'>
        <pose frame=''>0.10878 0 1.03843 0 -0 0</pose>
        <inertial>
          <pose frame=''>0.0081 0.0025 0.0113 0 -0 0</pose>
          <mass>0.9087</mass>
          <inertia>
            <ixx>0.0061</ixx>
            <ixy>-0</ixy>
            <ixz>0.0002</ixz>
            <iyy>0.0014</iyy>
            <iyz>-0.0001</iyz>
            <izz>0.0061</izz>
          </inertia>
        </inertial>
        <collision name='head_tilt_link_collision'>
          <pose frame=''>0 0 0 0 -0 0</pose>
          <geometry>
            <mesh>
              <scale>1 1 1</scale>
              <uri>/home/Jeremy/catkin_ws/src/fetch_ros/fetch_description/meshes/head_tilt_link_collision.STL</uri>
            </mesh>
          </geometry>
          <max_contacts>10</max_contacts>
          <surface>
            <contact>
              <ode/>
            </contact>
            <bounce/>
            <friction>
              <torsional>
                <ode/>
              </torsional>
              <ode/>
            </friction>
          </surface>
        </collision>
        <visual name='head_tilt_link_visual'>
          <pose frame=''>0 0 0 0 -0 0</pose>
          <geometry>
            <mesh>
              <scale>1 1 1</scale>
              <uri>/home/Jeremy/catkin_ws/src/fetch_ros/fetch_description/meshes/head_tilt_link.dae</uri>
            </mesh>
          </geometry>
        </visual>
        <gravity>1</gravity>
        <velocity_decay/>
        <sensor name='camera' type='depth'>
          <always_on>1</always_on>
          <update_rate>15</update_rate>
          <camera name='__default__'>
            <horizontal_fov>1.0472</horizontal_fov>
            <image>
              <format>B8G8R8</format>
              <width>640</width>
              <height>480</height>
            </image>
            <clip>
              <near>0.05</near>
              <far>50</far>
            </clip>
          </camera>
          <plugin name='head_camera_controller' filename='libgazebo_ros_openni_kinect.so'>
            <baseline>0.1</baseline>
            <alwaysOn>1</alwaysOn>
            <updateRate>15.0</updateRate>
            <cameraName>head_camera</cameraName>
            <imageTopicName>/head_camera/rgb/image_raw</imageTopicName>
            <cameraInfoTopicName>/head_camera/rgb/camera_info</cameraInfoTopicName>
            <depthImageTopicName>/head_camera/depth_registered/image_raw</depthImageTopicName>
            <depthImageCameraInfoTopicName>/head_camera/depth_registered/camera_info</depthImageCameraInfoTopicName>
            <pointCloudTopicName>/head_camera/depth_registered/points</pointCloudTopicName>
            <frameName>head_camera_rgb_optical_frame</frameName>
            <pointCloudCutoff>0.35</pointCloudCutoff>
            <pointCloudCutoffMax>4.5</pointCloudCutoffMax>
            <CxPrime>0</CxPrime>
            <Cx>0</Cx>
            <Cy>0</Cy>
            <focalLength>0</focalLength>
            <hackBaseline>0</hackBaseline>
            <robotNamespace>/</robotNamespace>
          </plugin>
          <pose frame=''>0.055 0.02 0.0225 0 -0 0</pose>
        </sensor>
        <self_collide>0</self_collide>
        <enable_wind>0</enable_wind>
        <kinematic>0</kinematic>
      </link>
      <joint name='head_tilt_joint' type='revolute'>
        <child>head_tilt_link</child>
        <parent>head_pan_link</parent>
        <axis>
          <xyz>0 1 -0</xyz>
          <limit>
            <lower>-0.76</lower>
            <upper>1.45</upper>
            <effort>0.68</effort>
            <velocity>1.57</velocity>
          </limit>
          <dynamics>
            <spring_reference>0</spring_reference>
            <spring_stiffness>0</spring_stiffness>
          </dynamics>
          <use_parent_model_frame>1</use_parent_model_frame>
        </axis>
      </joint>
      <link name='shoulder_pan_link'>
        <pose frame=''>0.03265 0 0.72601 0 -0 0</pose>
        <inertial>
          <pose frame=''>0.0927 -0.0056 0.0564 0 -0 0</pose>
          <mass>2.5587</mass>
          <inertia>
            <ixx>0.0043</ixx>
            <ixy>-0.0001</ixy>
            <ixz>0.001</ixz>
            <iyy>0.0087</iyy>
            <iyz>-0.0001</iyz>
            <izz>0.0087</izz>
          </inertia>
        </inertial>
        <collision name='shoulder_pan_link_collision'>
          <pose frame=''>0 0 0 0 -0 0</pose>
          <geometry>
            <mesh>
              <scale>1 1 1</scale>
              <uri>/home/Jeremy/catkin_ws/src/fetch_ros/fetch_description/meshes/shoulder_pan_link_collision.STL</uri>
            </mesh>
          </geometry>
          <max_contacts>10</max_contacts>
          <surface>
            <contact>
              <ode/>
            </contact>
            <bounce/>
            <friction>
              <torsional>
                <ode/>
              </torsional>
              <ode/>
            </friction>
          </surface>
        </collision>
        <visual name='shoulder_pan_link_visual'>
          <pose frame=''>0 0 0 0 -0 0</pose>
          <geometry>
            <mesh>
              <scale>1 1 1</scale>
              <uri>/home/Jeremy/catkin_ws/src/fetch_ros/fetch_description/meshes/shoulder_pan_link.dae</uri>
            </mesh>
          </geometry>
        </visual>
        <self_collide>0</self_collide>
        <enable_wind>0</enable_wind>
        <kinematic>0</kinematic>
      </link>
      <joint name='shoulder_pan_joint' type='revolute'>
        <child>shoulder_pan_link</child>
        <parent>torso_lift_link</parent>
        <axis>
          <xyz>0 0 1</xyz>
          <limit>
            <lower>-1.6056</lower>
            <upper>1.6056</upper>
            <effort>33.82</effort>
            <velocity>1.256</velocity>
          </limit>
          <dynamics>
            <damping>1</damping>
            <friction>0</friction>
            <spring_reference>0</spring_reference>
            <spring_stiffness>0</spring_stiffness>
          </dynamics>
          <use_parent_model_frame>1</use_parent_model_frame>
        </axis>
      </joint>
      <link name='shoulder_lift_link'>
        <pose frame=''>0.14965 0 0.78601 0 -0 0</pose>
        <inertial>
          <pose frame=''>0.1432 0.0072 -0.0001 0 -0 0</pose>
          <mass>2.6615</mass>
          <inertia>
            <ixx>0.0028</ixx>
            <ixy>-0.0021</ixy>
            <ixz>-0</ixz>
            <iyy>0.0111</iyy>
            <iyz>-0</iyz>
            <izz>0.0112</izz>
          </inertia>
        </inertial>
        <collision name='shoulder_lift_link_collision'>
          <pose frame=''>0 0 0 0 -0 0</pose>
          <geometry>
            <mesh>
              <scale>1 1 1</scale>
              <uri>/home/Jeremy/catkin_ws/src/fetch_ros/fetch_description/meshes/shoulder_lift_link_collision.STL</uri>
            </mesh>
          </geometry>
          <max_contacts>10</max_contacts>
          <surface>
            <contact>
              <ode/>
            </contact>
            <bounce/>
            <friction>
              <torsional>
                <ode/>
              </torsional>
              <ode/>
            </friction>
          </surface>
        </collision>
        <visual name='shoulder_lift_link_visual'>
          <pose frame=''>0 0 0 0 -0 0</pose>
          <geometry>
            <mesh>
              <scale>1 1 1</scale>
              <uri>/home/Jeremy/catkin_ws/src/fetch_ros/fetch_description/meshes/shoulder_lift_link.dae</uri>
            </mesh>
          </geometry>
        </visual>
        <self_collide>0</self_collide>
        <enable_wind>0</enable_wind>
        <kinematic>0</kinematic>
      </link>
      <joint name='shoulder_lift_joint' type='revolute'>
        <child>shoulder_lift_link</child>
        <parent>shoulder_pan_link</parent>
        <axis>
          <xyz>0 1 -0</xyz>
          <limit>
            <lower>-1.221</lower>
            <upper>1.518</upper>
            <effort>131.76</effort>
            <velocity>1.454</velocity>
          </limit>
          <dynamics>
            <damping>1</damping>
            <friction>0</friction>
            <spring_reference>0</spring_reference>
            <spring_stiffness>0</spring_stiffness>
          </dynamics>
          <use_parent_model_frame>1</use_parent_model_frame>
        </axis>
      </joint>
      <link name='upperarm_roll_link'>
        <pose frame=''>0.36865 0 0.78601 0 -0 0</pose>
        <inertial>
          <pose frame=''>0.1165 0.0014 0 0 -0 0</pose>
          <mass>2.3311</mass>
          <inertia>
            <ixx>0.0019</ixx>
            <ixy>-0.0001</ixy>
            <ixz>0</ixz>
            <iyy>0.0045</iyy>
            <iyz>0</iyz>
            <izz>0.0047</izz>
          </inertia>
        </inertial>
        <collision name='upperarm_roll_link_collision'>
          <pose frame=''>0 0 0 0 -0 0</pose>
          <geometry>
            <mesh>
              <scale>1 1 1</scale>
              <uri>/home/Jeremy/catkin_ws/src/fetch_ros/fetch_description/meshes/upperarm_roll_link_collision.STL</uri>
            </mesh>
          </geometry>
          <max_contacts>10</max_contacts>
          <surface>
            <contact>
              <ode/>
            </contact>
            <bounce/>
            <friction>
              <torsional>
                <ode/>
              </torsional>
              <ode/>
            </friction>
          </surface>
        </collision>
        <visual name='upperarm_roll_link_visual'>
          <pose frame=''>0 0 0 0 -0 0</pose>
          <geometry>
            <mesh>
              <scale>1 1 1</scale>
              <uri>/home/Jeremy/catkin_ws/src/fetch_ros/fetch_description/meshes/upperarm_roll_link.dae</uri>
            </mesh>
          </geometry>
        </visual>
        <self_collide>0</self_collide>
        <enable_wind>0</enable_wind>
        <kinematic>0</kinematic>
      </link>
      <joint name='upperarm_roll_joint' type='revolute'>
        <child>upperarm_roll_link</child>
        <parent>shoulder_lift_link</parent>
        <axis>
          <xyz>1 0 0</xyz>
          <limit>
            <lower>-1e+16</lower>
            <upper>1e+16</upper>
          </limit>
          <dynamics>
            <damping>5</damping>
            <friction>0</friction>
            <spring_reference>0</spring_reference>
            <spring_stiffness>0</spring_stiffness>
          </dynamics>
          <use_parent_model_frame>1</use_parent_model_frame>
        </axis>
      </joint>
      <link name='elbow_flex_link'>
        <pose frame=''>0.50165 0 0.78601 0 -0 0</pose>
        <inertial>
          <pose frame=''>0.1279 0.0073 0 0 -0 0</pose>
          <mass>2.1299</mass>
          <inertia>
            <ixx>0.0024</ixx>
            <ixy>-0.0016</ixy>
            <ixz>0</ixz>
            <iyy>0.0082</iyy>
            <iyz>-0</iyz>
            <izz>0.0084</izz>
          </inertia>
        </inertial>
        <collision name='elbow_flex_link_collision'>
          <pose frame=''>0 0 0 0 -0 0</pose>
          <geometry>
            <mesh>
              <scale>1 1 1</scale>
              <uri>/home/Jeremy/catkin_ws/src/fetch_ros/fetch_description/meshes/elbow_flex_link_collision.STL</uri>
            </mesh>
          </geometry>
          <max_contacts>10</max_contacts>
          <surface>
            <contact>
              <ode/>
            </contact>
            <bounce/>
            <friction>
              <torsional>
                <ode/>
              </torsional>
              <ode/>
            </friction>
          </surface>
        </collision>
        <visual name='elbow_flex_link_visual'>
          <pose frame=''>0 0 0 0 -0 0</pose>
          <geometry>
            <mesh>
              <scale>1 1 1</scale>
              <uri>/home/Jeremy/catkin_ws/src/fetch_ros/fetch_description/meshes/elbow_flex_link.dae</uri>
            </mesh>
          </geometry>
        </visual>
        <self_collide>0</self_collide>
        <enable_wind>0</enable_wind>
        <kinematic>0</kinematic>
      </link>
      <joint name='elbow_flex_joint' type='revolute'>
        <child>elbow_flex_link</child>
        <parent>upperarm_roll_link</parent>
        <axis>
          <xyz>0 1 -0</xyz>
          <limit>
            <lower>-2.251</lower>
            <upper>2.251</upper>
            <effort>66.18</effort>
            <velocity>1.521</velocity>
          </limit>
          <dynamics>
            <damping>1</damping>
            <friction>0</friction>
            <spring_reference>0</spring_reference>
            <spring_stiffness>0</spring_stiffness>
          </dynamics>
          <use_parent_model_frame>1</use_parent_model_frame>
        </axis>
      </joint>
      <link name='forearm_roll_link'>
        <pose frame=''>0.69865 0 0.78601 0 -0 0</pose>
        <inertial>
          <pose frame=''>0.1097 -0.0266 0 0 -0 0</pose>
          <mass>1.6563</mass>
          <inertia>
            <ixx>0.0016</ixx>
            <ixy>-0.0003</ixy>
            <ixz>0</ixz>
            <iyy>0.003</iyy>
            <iyz>-0</iyz>
            <izz>0.0035</izz>
          </inertia>
        </inertial>
        <collision name='forearm_roll_link_collision'>
          <pose frame=''>0 0 0 0 -0 0</pose>
          <geometry>
            <mesh>
              <scale>1 1 1</scale>
              <uri>/home/Jeremy/catkin_ws/src/fetch_ros/fetch_description/meshes/forearm_roll_link_collision.STL</uri>
            </mesh>
          </geometry>
          <max_contacts>10</max_contacts>
          <surface>
            <contact>
              <ode/>
            </contact>
            <bounce/>
            <friction>
              <torsional>
                <ode/>
              </torsional>
              <ode/>
            </friction>
          </surface>
        </collision>
        <visual name='forearm_roll_link_visual'>
          <pose frame=''>0 0 0 0 -0 0</pose>
          <geometry>
            <mesh>
              <scale>1 1 1</scale>
              <uri>/home/Jeremy/catkin_ws/src/fetch_ros/fetch_description/meshes/forearm_roll_link.dae</uri>
            </mesh>
          </geometry>
        </visual>
        <self_collide>0</self_collide>
        <enable_wind>0</enable_wind>
        <kinematic>0</kinematic>
      </link>
      <joint name='forearm_roll_joint' type='revolute'>
        <child>forearm_roll_link</child>
        <parent>elbow_flex_link</parent>
        <axis>
          <xyz>1 0 0</xyz>
          <limit>
            <lower>-1e+16</lower>
            <upper>1e+16</upper>
          </limit>
          <dynamics>
            <damping>5</damping>
            <friction>0</friction>
            <spring_reference>0</spring_reference>
            <spring_stiffness>0</spring_stiffness>
          </dynamics>
          <use_parent_model_frame>1</use_parent_model_frame>
        </axis>
        <physics>
          <ode>
            <implicit_spring_damper>1</implicit_spring_damper>
            <cfm_damping>1</cfm_damping>
            <limit>
              <cfm>0</cfm>
              <erp>0.2</erp>
            </limit>
          </ode>
        </physics>
      </joint>
      <link name='wrist_flex_link'>
        <pose frame=''>0.82315 0 0.78601 0 -0 0</pose>
        <inertial>
          <pose frame=''>0.0882 0.0009 -0.0001 0 -0 0</pose>
          <mass>1.725</mass>
          <inertia>
            <ixx>0.0018</ixx>
            <ixy>-0.0001</ixy>
            <ixz>-0</ixz>
            <iyy>0.0042</iyy>
            <iyz>0</iyz>
            <izz>0.0042</izz>
          </inertia>
        </inertial>
        <collision name='wrist_flex_link_collision'>
          <pose frame=''>0 0 0 0 -0 0</pose>
          <geometry>
            <mesh>
              <scale>1 1 1</scale>
              <uri>/home/Jeremy/catkin_ws/src/fetch_ros/fetch_description/meshes/wrist_flex_link_collision.STL</uri>
            </mesh>
          </geometry>
          <max_contacts>10</max_contacts>
          <surface>
            <contact>
              <ode/>
            </contact>
            <bounce/>
            <friction>
              <torsional>
                <ode/>
              </torsional>
              <ode/>
            </friction>
          </surface>
        </collision>
        <visual name='wrist_flex_link_visual'>
          <pose frame=''>0 0 0 0 -0 0</pose>
          <geometry>
            <mesh>
              <scale>1 1 1</scale>
              <uri>/home/Jeremy/catkin_ws/src/fetch_ros/fetch_description/meshes/wrist_flex_link.dae</uri>
            </mesh>
          </geometry>
        </visual>
        <self_collide>0</self_collide>
        <enable_wind>0</enable_wind>
        <kinematic>0</kinematic>
      </link>
      <joint name='wrist_flex_joint' type='revolute'>
        <child>wrist_flex_link</child>
        <parent>forearm_roll_link</parent>
        <axis>
          <xyz>0 1 -0</xyz>
          <limit>
            <lower>-2.16</lower>
            <upper>2.16</upper>
            <effort>25.7</effort>
            <velocity>2.268</velocity>
          </limit>
          <dynamics>
            <damping>1</damping>
            <friction>0</friction>
            <spring_reference>0</spring_reference>
            <spring_stiffness>0</spring_stiffness>
          </dynamics>
          <use_parent_model_frame>1</use_parent_model_frame>
        </axis>
      </joint>
      <link name='wrist_roll_link'>
        <pose frame=''>0.96165 0 0.78601 0 -0 0</pose>
        <inertial>
          <pose frame=''>0.070966 -5.9e-05 -0.001577 0 -0 0</pose>
          <mass>1.6529</mass>
          <inertia>
            <ixx>0.00140031</ixx>
            <ixy>4.16123e-06</ixy>
            <ixz>1.24837e-05</ixz>
            <iyy>0.00255747</iyy>
            <iyz>-9.32314e-08</iyz>
            <izz>0.00305722</izz>
          </inertia>
        </inertial>
        <collision name='wrist_roll_link_collision'>
          <pose frame=''>0 0 0 0 -0 0</pose>
          <geometry>
            <mesh>
              <scale>1 1 1</scale>
              <uri>/home/Jeremy/catkin_ws/src/fetch_ros/fetch_description/meshes/wrist_roll_link_collision.STL</uri>
            </mesh>
          </geometry>
          <max_contacts>10</max_contacts>
          <surface>
            <contact>
              <ode/>
            </contact>
            <bounce/>
            <friction>
              <torsional>
                <ode/>
              </torsional>
              <ode/>
            </friction>
          </surface>
        </collision>
        <collision name='wrist_roll_link_fixed_joint_lump__gripper_link_collision_1'>
          <pose frame=''>0.16645 0 0 0 -0 0</pose>
          <geometry>
            <mesh>
              <scale>1 1 1</scale>
              <uri>/home/Jeremy/catkin_ws/src/fetch_ros/fetch_description/meshes/gripper_link.STL</uri>
            </mesh>
          </geometry>
          <max_contacts>10</max_contacts>
          <surface>
            <contact>
              <ode/>
            </contact>
            <bounce/>
            <friction>
              <torsional>
                <ode/>
              </torsional>
              <ode/>
            </friction>
          </surface>
        </collision>
        <visual name='wrist_roll_link_visual'>
          <pose frame=''>0 0 0 0 -0 0</pose>
          <geometry>
            <mesh>
              <scale>1 1 1</scale>
              <uri>/home/Jeremy/catkin_ws/src/fetch_ros/fetch_description/meshes/wrist_roll_link.dae</uri>
            </mesh>
          </geometry>
        </visual>
        <visual name='wrist_roll_link_fixed_joint_lump__gripper_link_visual_1'>
          <pose frame=''>0.16645 0 0 0 -0 0</pose>
          <geometry>
            <mesh>
              <scale>1 1 1</scale>
              <uri>/home/Jeremy/catkin_ws/src/fetch_ros/fetch_description/meshes/gripper_link.dae</uri>
            </mesh>
          </geometry>
        </visual>
        <self_collide>0</self_collide>
        <enable_wind>0</enable_wind>
        <kinematic>0</kinematic>
      </link>
      <joint name='wrist_roll_joint' type='revolute'>
        <child>wrist_roll_link</child>
        <parent>wrist_flex_link</parent>
        <axis>
          <xyz>1 0 0</xyz>
          <limit>
            <lower>-1e+16</lower>
            <upper>1e+16</upper>
          </limit>
          <dynamics>
            <damping>5</damping>
            <friction>0</friction>
            <spring_reference>0</spring_reference>
            <spring_stiffness>0</spring_stiffness>
          </dynamics>
          <use_parent_model_frame>1</use_parent_model_frame>
        </axis>
        <physics>
          <ode>
            <implicit_spring_damper>1</implicit_spring_damper>
            <cfm_damping>1</cfm_damping>
            <limit>
              <cfm>0</cfm>
              <erp>0.2</erp>
            </limit>
          </ode>
        </physics>
      </joint>
      <link name='l_gripper_finger_link'>
        <pose frame=''>1.1281 -0.015425 0.78601 0 -0 0</pose>
        <inertial>
          <pose frame=''>-0.01 0 0 0 -0 0</pose>
          <mass>0.0798</mass>
          <inertia>
            <ixx>0.002</ixx>
            <ixy>0</ixy>
            <ixz>0</ixz>
            <iyy>0</iyy>
            <iyz>0</iyz>
            <izz>0</izz>
          </inertia>
        </inertial>
        <collision name='l_gripper_finger_link_collision'>
          <pose frame=''>0 -0.101425 0 0 -0 0</pose>
          <geometry>
            <mesh>
              <scale>1 1 1</scale>
              <uri>/home/Jeremy/catkin_ws/src/fetch_ros/fetch_description/meshes/l_gripper_finger_link.STL</uri>
            </mesh>
          </geometry>
          <surface>
            <contact>
              <ode>
                <kp>1e+06</kp>
                <kd>100</kd>
                <max_vel>1</max_vel>
                <min_depth>0.001</min_depth>
              </ode>
            </contact>
            <friction>
              <ode>
                <mu>30</mu>
                <mu2>30</mu2>
              </ode>
              <torsional>
                <ode/>
              </torsional>
            </friction>
            <bounce/>
          </surface>
          <max_contacts>10</max_contacts>
        </collision>
        <visual name='l_gripper_finger_link_visual'>
          <pose frame=''>0 -0.101425 0 0 -0 0</pose>
          <geometry>
            <mesh>
              <scale>1 1 1</scale>
              <uri>/home/Jeremy/catkin_ws/src/fetch_ros/fetch_description/meshes/l_gripper_finger_link.STL</uri>
            </mesh>
          </geometry>
          <material>
            <script>
              <name>Gazebo/Grey</name>
              <uri>file://media/materials/scripts/gazebo.material</uri>
            </script>
          </material>
        </visual>
        <gravity>1</gravity>
        <velocity_decay/>
        <self_collide>0</self_collide>
        <enable_wind>0</enable_wind>
        <kinematic>0</kinematic>
      </link>
      <joint name='l_gripper_finger_joint' type='prismatic'>
        <child>l_gripper_finger_link</child>
        <parent>wrist_roll_link</parent>
        <axis>
          <xyz>0 -1 0</xyz>
          <limit>
            <lower>0</lower>
            <upper>0.05</upper>
            <effort>60</effort>
            <velocity>0.05</velocity>
          </limit>
          <dynamics>
            <damping>100</damping>
            <friction>0</friction>
            <spring_reference>0</spring_reference>
            <spring_stiffness>0</spring_stiffness>
          </dynamics>
          <use_parent_model_frame>1</use_parent_model_frame>
        </axis>
      </joint>
      <link name='r_gripper_finger_link'>
        <pose frame=''>1.1281 0.015425 0.78601 0 -0 0</pose>
        <inertial>
          <pose frame=''>-0.01 0 0 0 -0 0</pose>
          <mass>0.0798</mass>
          <inertia>
            <ixx>0.002</ixx>
            <ixy>0</ixy>
            <ixz>0</ixz>
            <iyy>0</iyy>
            <iyz>0</iyz>
            <izz>0</izz>
          </inertia>
        </inertial>
        <collision name='r_gripper_finger_link_collision'>
          <pose frame=''>0 0.101425 0 0 -0 0</pose>
          <geometry>
            <mesh>
              <scale>1 1 1</scale>
              <uri>/home/Jeremy/catkin_ws/src/fetch_ros/fetch_description/meshes/r_gripper_finger_link.STL</uri>
            </mesh>
          </geometry>
          <surface>
            <contact>
              <ode>
                <kp>1e+06</kp>
                <kd>100</kd>
                <max_vel>1</max_vel>
                <min_depth>0.001</min_depth>
              </ode>
            </contact>
            <friction>
              <ode>
                <mu>30</mu>
                <mu2>30</mu2>
              </ode>
              <torsional>
                <ode/>
              </torsional>
            </friction>
            <bounce/>
          </surface>
          <max_contacts>10</max_contacts>
        </collision>
        <visual name='r_gripper_finger_link_visual'>
          <pose frame=''>0 0.101425 0 0 -0 0</pose>
          <geometry>
            <mesh>
              <scale>1 1 1</scale>
              <uri>/home/Jeremy/catkin_ws/src/fetch_ros/fetch_description/meshes/r_gripper_finger_link.STL</uri>
            </mesh>
          </geometry>
          <material>
            <script>
              <name>Gazebo/Grey</name>
              <uri>file://media/materials/scripts/gazebo.material</uri>
            </script>
          </material>
        </visual>
        <gravity>1</gravity>
        <velocity_decay/>
        <self_collide>0</self_collide>
        <enable_wind>0</enable_wind>
        <kinematic>0</kinematic>
      </link>
      <joint name='r_gripper_finger_joint' type='prismatic'>
        <child>r_gripper_finger_link</child>
        <parent>wrist_roll_link</parent>
        <axis>
          <xyz>0 1 -0</xyz>
          <limit>
            <lower>0</lower>
            <upper>0.05</upper>
            <effort>60</effort>
            <velocity>0.05</velocity>
          </limit>
          <dynamics>
            <damping>100</damping>
            <friction>0</friction>
            <spring_reference>0</spring_reference>
            <spring_stiffness>0</spring_stiffness>
          </dynamics>
          <use_parent_model_frame>1</use_parent_model_frame>
        </axis>
      </joint>
      <static>0</static>
      <plugin name='fetch_gazebo_plugin' filename='libfetch_gazebo_plugin.so'>
        <robotNamespace>/</robotNamespace>
      </plugin>
      <pose frame=''>0 0.571285 0 0 0 -1.57</pose>
    </model>
    <model name='gearbox_bottom_grey3_clone'>
      <static>0</static>
      <link name='link'>
        <inertial>
          <pose frame=''>0 0 0.026185 0 -0 0</pose>
          <mass>0.370561</mass>
          <inertia>
            <ixx>0.000131217</ixx>
            <ixy>0</ixy>
            <ixz>0</ixz>
            <iyy>0.000981018</iyy>
            <iyz>0</iyz>
            <izz>0.000942848</izz>
          </inertia>
        </inertial>
        <collision name='collision'>
          <geometry>
            <mesh>
              <uri>model://gearbox_bottom_grey/meshes/gearbox_bottom_simple.stl</uri>
              <scale>1 1 1</scale>
            </mesh>
          </geometry>
          <surface>
            <friction>
              <ode>
                <mu>30</mu>
                <mu2>30</mu2>
              </ode>
              <torsional>
                <ode/>
              </torsional>
            </friction>
            <contact>
              <ode/>
            </contact>
            <bounce/>
          </surface>
          <max_contacts>10</max_contacts>
        </collision>
        <visual name='visual'>
          <geometry>
            <mesh>
              <uri>model://gearbox_bottom_grey/meshes/gearBoxBottom_grey.dae</uri>
              <scale>1 1 1</scale>
            </mesh>
          </geometry>
        </visual>
        <velocity_decay>
          <linear>0</linear>
          <angular>0</angular>
        </velocity_decay>
        <self_collide>0</self_collide>
        <kinematic>0</kinematic>
        <gravity>1</gravity>
        <enable_wind>0</enable_wind>
      </link>
      <pose frame=''>-0.441816 1.18132 0.837371 3.14159 -5e-06 -2.47799</pose>
    </model>
    <model name='gearbox_top_grey2_clone'>
      <static>0</static>
      <link name='link'>
        <inertial>
          <pose frame=''>0 0 0 0 -0 0</pose>
          <mass>0.228259</mass>
          <inertia>
            <ixx>4.84526e-05</ixx>
            <ixy>0</ixy>
            <ixz>0</ixz>
            <iyy>0.000571913</iyy>
            <iyz>0</iyz>
            <izz>0.000580777</izz>
          </inertia>
        </inertial>
        <collision name='collision'>
          <geometry>
            <mesh>
              <uri>model://gearbox_top_grey/meshes/gearBoxTop_v3.stl</uri>
              <scale>1 1 1</scale>
            </mesh>
          </geometry>
          <surface>
            <friction>
              <ode>
                <mu>30</mu>
                <mu2>30</mu2>
              </ode>
              <torsional>
                <ode/>
              </torsional>
            </friction>
            <contact>
              <ode/>
            </contact>
            <bounce/>
          </surface>
          <max_contacts>10</max_contacts>
        </collision>
        <visual name='visual'>
          <geometry>
            <mesh>
              <uri>model://gearbox_top_grey/meshes/gearBoxTop_grey.dae</uri>
              <scale>1 1 1</scale>
            </mesh>
          </geometry>
        </visual>
        <velocity_decay>
          <linear>0</linear>
          <angular>0</angular>
        </velocity_decay>
        <self_collide>0</self_collide>
        <kinematic>0</kinematic>
        <gravity>1</gravity>
        <enable_wind>0</enable_wind>
      </link>
      <pose frame=''>-0.211755 1.34042 0.796851 -3.14131 7e-06 0.323088</pose>
    </model>
    <model name='large_gear_1_clone'>
      <static>0</static>
      <link name='link'>
        <inertial>
          <pose frame=''>0 0 0.057592 0 -0 0</pose>
          <mass>0.238024</mass>
          <inertia>
            <ixx>0.000343121</ixx>
            <ixy>0</ixy>
            <ixz>0</ixz>
            <iyy>0.000343121</iyy>
            <iyz>0</iyz>
            <izz>0.000159917</izz>
          </inertia>
        </inertial>
        <collision name='collision'>
          <geometry>
            <mesh>
              <uri>model://gearbox_largegear_grey/meshes/largeGear_v5.stl</uri>
              <scale>1 1 1</scale>
            </mesh>
          </geometry>
          <surface>
            <friction>
              <ode>
                <mu>30</mu>
                <mu2>30</mu2>
              </ode>
              <torsional>
                <ode/>
              </torsional>
            </friction>
            <contact>
              <ode>
                <soft_cfm>0</soft_cfm>
                <soft_erp>0.2</soft_erp>
                <kp>1e+13</kp>
                <kd>1</kd>
                <max_vel>0.01</max_vel>
                <min_depth>0</min_depth>
              </ode>
            </contact>
            <bounce/>
          </surface>
          <max_contacts>10</max_contacts>
        </collision>
        <visual name='visual'>
          <geometry>
            <mesh>
              <uri>model://gearbox_largegear_grey/meshes/largeGear_grey.dae</uri>
              <scale>1 1 1</scale>
            </mesh>
          </geometry>
        </visual>
        <velocity_decay>
          <linear>0</linear>
          <angular>0</angular>
        </velocity_decay>
        <self_collide>0</self_collide>
        <kinematic>0</kinematic>
        <gravity>1</gravity>
        <enable_wind>0</enable_wind>
      </link>
      <pose frame=''>-0.473817 1.33445 0.801693 0.001437 -0.003267 0.068244</pose>
    </model>
    <model name='large_gear_3_clone'>
      <static>0</static>
      <link name='link'>
        <inertial>
          <pose frame=''>0 0 0.057592 0 -0 0</pose>
          <mass>0.238024</mass>
          <inertia>
            <ixx>0.000343121</ixx>
            <ixy>0</ixy>
            <ixz>0</ixz>
            <iyy>0.000343121</iyy>
            <iyz>0</iyz>
            <izz>0.000159917</izz>
          </inertia>
        </inertial>
        <collision name='collision'>
          <geometry>
            <mesh>
              <uri>model://gearbox_largegear_grey/meshes/largeGear_v5.stl</uri>
              <scale>1 1 1</scale>
            </mesh>
          </geometry>
          <surface>
            <friction>
              <ode>
                <mu>30</mu>
                <mu2>30</mu2>
              </ode>
              <torsional>
                <ode/>
              </torsional>
            </friction>
            <contact>
              <ode>
                <soft_cfm>0</soft_cfm>
                <soft_erp>0.2</soft_erp>
                <kp>1e+13</kp>
                <kd>1</kd>
                <max_vel>0.01</max_vel>
                <min_depth>0</min_depth>
              </ode>
            </contact>
            <bounce/>
          </surface>
          <max_contacts>10</max_contacts>
        </collision>
        <visual name='visual'>
          <geometry>
            <mesh>
              <uri>model://gearbox_largegear_grey/meshes/largeGear_grey.dae</uri>
              <scale>1 1 1</scale>
            </mesh>
          </geometry>
        </visual>
        <velocity_decay>
          <linear>0</linear>
          <angular>0</angular>
        </velocity_decay>
        <self_collide>0</self_collide>
        <kinematic>0</kinematic>
        <gravity>1</gravity>
        <enable_wind>0</enable_wind>
      </link>
      <pose frame=''>0.009864 1.1952 0.836874 1.90739 -0.898207 -0.083863</pose>
    </model>
    <model name='small_gear_3_clone'>
      <static>0</static>
      <link name='link'>
        <inertial>
          <pose frame=''>0 0 0.022095 0 -0 0</pose>
          <mass>0.0572118</mass>
          <inertia>
            <ixx>1.47769e-05</ixx>
            <ixy>0</ixy>
            <ixz>0</ixz>
            <iyy>1.47769e-05</iyy>
            <iyz>0</iyz>
            <izz>1.09336e-05</izz>
          </inertia>
        </inertial>
        <collision name='collision'>
          <geometry>
            <mesh>
              <uri>model://gearbox_smallgear_grey/meshes/smallGear_simple_v2.stl</uri>
              <scale>1 1 1</scale>
            </mesh>
          </geometry>
          <surface>
            <friction>
              <ode>
                <mu>30</mu>
                <mu2>30</mu2>
              </ode>
              <torsional>
                <ode/>
              </torsional>
            </friction>
            <contact>
              <ode/>
            </contact>
            <bounce/>
          </surface>
          <max_contacts>10</max_contacts>
        </collision>
        <visual name='visual'>
          <geometry>
            <mesh>
              <uri>model://gearbox_smallgear_grey/meshes/smallGear_grey.dae</uri>
              <scale>1 1 1</scale>
            </mesh>
          </geometry>
        </visual>
        <velocity_decay>
          <linear>0</linear>
          <angular>0</angular>
        </velocity_decay>
        <self_collide>0</self_collide>
        <kinematic>0</kinematic>
        <gravity>1</gravity>
        <enable_wind>0</enable_wind>
      </link>
      <pose frame=''>-0.625473 1.16899 0.805848 1.19364 -0.18285 0.159918</pose>
    </model>
    <model name='small_gear_2_clone'>
      <static>0</static>
      <link name='link'>
        <inertial>
          <pose frame=''>0 0 0.022095 0 -0 0</pose>
          <mass>0.0572118</mass>
          <inertia>
            <ixx>1.47769e-05</ixx>
            <ixy>0</ixy>
            <ixz>0</ixz>
            <iyy>1.47769e-05</iyy>
            <iyz>0</iyz>
            <izz>1.09336e-05</izz>
          </inertia>
        </inertial>
        <collision name='collision'>
          <geometry>
            <mesh>
              <uri>model://gearbox_smallgear_grey/meshes/smallGear_simple_v2.stl</uri>
              <scale>1 1 1</scale>
            </mesh>
          </geometry>
          <surface>
            <friction>
              <ode>
                <mu>30</mu>
                <mu2>30</mu2>
              </ode>
              <torsional>
                <ode/>
              </torsional>
            </friction>
            <contact>
              <ode/>
            </contact>
            <bounce/>
          </surface>
          <max_contacts>10</max_contacts>
        </collision>
        <visual name='visual'>
          <geometry>
            <mesh>
              <uri>model://gearbox_smallgear_grey/meshes/smallGear_grey.dae</uri>
              <scale>1 1 1</scale>
            </mesh>
          </geometry>
        </visual>
        <velocity_decay>
          <linear>0</linear>
          <angular>0</angular>
        </velocity_decay>
        <self_collide>0</self_collide>
        <kinematic>0</kinematic>
        <gravity>1</gravity>
        <enable_wind>0</enable_wind>
      </link>
      <pose frame=''>-0.052948 1.26854 0.801713 2.1e-05 -8.7e-05 -0.048101</pose>
    </model>
    <model name='gearbox_bolt_grey5_clone'>
      <static>0</static>
      <link name='link'>
        <inertial>
          <pose frame=''>0 0 0.030633 0 -0 0</pose>
          <mass>0.0592855</mass>
          <inertia>
            <ixx>2.29775e-05</ixx>
            <ixy>0</ixy>
            <ixz>0</ixz>
            <iyy>2.29905e-05</iyy>
            <iyz>0</iyz>
            <izz>8.87979e-06</izz>
          </inertia>
        </inertial>
        <collision name='collision'>
          <geometry>
            <mesh>
              <uri>model://gearbox_bolt_grey/meshes/gear_bolt_simple.stl</uri>
              <scale>1 1 1</scale>
            </mesh>
          </geometry>
          <surface>
            <friction>
              <ode>
                <mu>30</mu>
                <mu2>30</mu2>
              </ode>
              <torsional>
                <ode/>
              </torsional>
            </friction>
            <contact>
              <ode/>
            </contact>
            <bounce/>
          </surface>
          <max_contacts>10</max_contacts>
        </collision>
        <visual name='visual'>
          <geometry>
            <mesh>
              <uri>model://gearbox_bolt_grey/meshes/screw_grey.dae</uri>
              <scale>1 1 1</scale>
            </mesh>
          </geometry>
        </visual>
        <velocity_decay>
          <linear>0</linear>
          <angular>0</angular>
        </velocity_decay>
        <self_collide>0</self_collide>
        <kinematic>0</kinematic>
        <gravity>1</gravity>
        <enable_wind>0</enable_wind>
      </link>
      <pose frame=''>-0.272577 1.13342 0.790845 -5.3e-05 -0.000116 0.042915</pose>
    </model>
    <model name='gearbox_bolt_grey12_clone'>
      <static>0</static>
      <link name='link'>
        <inertial>
          <pose frame=''>0 0 0.030633 0 -0 0</pose>
          <mass>0.0592855</mass>
          <inertia>
            <ixx>2.29775e-05</ixx>
            <ixy>0</ixy>
            <ixz>0</ixz>
            <iyy>2.29905e-05</iyy>
            <iyz>0</iyz>
            <izz>8.87979e-06</izz>
          </inertia>
        </inertial>
        <collision name='collision'>
          <geometry>
            <mesh>
              <uri>model://gearbox_bolt_grey/meshes/gear_bolt_simple.stl</uri>
              <scale>1 1 1</scale>
            </mesh>
          </geometry>
          <surface>
            <friction>
              <ode>
                <mu>30</mu>
                <mu2>30</mu2>
              </ode>
              <torsional>
                <ode/>
              </torsional>
            </friction>
            <contact>
              <ode/>
            </contact>
            <bounce/>
          </surface>
          <max_contacts>10</max_contacts>
        </collision>
        <visual name='visual'>
          <geometry>
            <mesh>
              <uri>model://gearbox_bolt_grey/meshes/screw_grey.dae</uri>
              <scale>1 1 1</scale>
            </mesh>
          </geometry>
        </visual>
        <velocity_decay>
          <linear>0</linear>
          <angular>0</angular>
        </velocity_decay>
        <self_collide>0</self_collide>
        <kinematic>0</kinematic>
        <gravity>1</gravity>
        <enable_wind>0</enable_wind>
      </link>
      <pose frame=''>-0.141984 1.22623 0.80689 1.72907 -0.582572 -0.767585</pose>
    </model>
    <state world_name='default'>
      <sim_time>2497 806000000</sim_time>
      <real_time>1843 6783165</real_time>
      <wall_time>1633624550 932858121</wall_time>
      <iterations>1659859</iterations>
      <model name='fetch'>
        <pose frame=''>-0.248902 -0.331653 0.004772 -1e-05 1e-06 1.583</pose>
        <scale>1 1 1</scale>
        <link name='base_link'>
          <pose frame=''>-0.248902 -0.331653 0.004772 -1e-05 1e-06 1.583</pose>
          <velocity>-0 5e-06 -0.001163 -0.000946 -9.5e-05 0</velocity>
          <acceleration>-0.028056 0.164301 -2.97705 -1.43967 -0.225176 -0.508588</acceleration>
          <wrench>-2.34147 13.7121 -248.456 0 -0 0</wrench>
        </link>
        <link name='bellows_link'>
          <pose frame=''>-0.247847 -0.418521 0.555541 -1e-05 1e-06 1.583</pose>
          <velocity>-6.8e-05 0.000521 0.000288 -0.001001 1.8e-05 -5.8e-05</velocity>
          <acceleration>-0.167669 0.6138 0.092326 -0.693006 -0.091124 -0.117087</acceleration>
          <wrench>-0.028399 0.103962 0.015638 0 -0 0</wrench>
        </link>
        <link name='elbow_flex_link'>
          <pose frame=''>-0.717506 -0.271519 1.15068 -0.038588 -1.56995 3.12154</pose>
          <velocity>-0.000453 -0.004758 0.002312 -0.011241 0.052407 0.012333</velocity>
          <acceleration>13.3129 -6.73399 -1.06992 -2.73303 0.377775 -1.3962</acceleration>
          <wrench>28.3552 -14.3427 -2.27883 0 -0 0</wrench>
        </link>
        <link name='forearm_roll_link'>
          <pose frame=''>-0.717672 -0.271516 1.34768 3.09834 -1.56995 3.12184</pose>
          <velocity>0.009616 -0.00297 0.002221 -0.009882 0.051579 -1.98205</velocity>
          <acceleration>-73.4124 3.31664 -0.745972 -1.64075 -1.0668 -2.32458</acceleration>
          <wrench>-121.593 5.49336 -1.23555 0 -0 0</wrench>
        </link>
        <link name='head_pan_link'>
          <pose frame=''>-0.248503 -0.3654 1.34514 -1e-05 1e-06 1.58297</pose>
          <velocity>-7.8e-05 0.001277 -0.009607 -0.000954 -1.8e-05 0.000568</velocity>
          <acceleration>-0.275868 2.09531 9.69935 0.049276 0.567867 1.49454</acceleration>
          <wrench>-0.622249 4.72617 21.8778 0 -0 0</wrench>
        </link>
        <link name='head_tilt_link'>
          <pose frame=''>-0.250239 -0.22288 1.40314 -1.7e-05 0.934743 1.58296</pose>
          <velocity>-0.00016 0.001331 -0.009742 0.115219 0.001397 0.000571</velocity>
          <acceleration>-0.364532 2.13493 9.33359 -0.505103 0.787899 -0.528689</acceleration>
          <wrench>-0.33125 1.94001 8.48143 0 -0 0</wrench>
        </link>
        <link name='l_gripper_finger_link'>
          <pose frame=''>-0.722281 -0.336694 1.77713 3.09454 -1.56996 3.12358</pose>
          <velocity>0.022325 0.164942 0.002209 0.001 0.001472 0.000581</velocity>
          <acceleration>48.8772 329.849 -1.52653 -0.745826 1.28895 1.01967</acceleration>
          <wrench>3.9004 26.3219 -0.121817 0 -0 0</wrench>
        </link>
        <link name='l_wheel_link'>
          <pose frame=''>-0.436284 -0.33265 0.060095 -1.1e-05 0.371045 1.583</pose>
          <velocity>-5e-06 5.8e-05 -0.001179 -0.00096 -8.7e-05 -5e-06</velocity>
          <acceleration>-0.014276 0.093418 -3.06584 -0.27319 -0.254997 -0.011422</acceleration>
          <wrench>-0.06216 0.406759 -13.3493 0 -0 0</wrench>
        </link>
        <link name='r_gripper_finger_link'>
          <pose frame=''>-0.713786 -0.206326 1.77714 3.0951 -1.56996 3.12302</pose>
          <velocity>-0.000427 -0.169836 0.0022 -0.00194 -0.010169 -0.001785</velocity>
          <acceleration>2.53873 -339.696 -1.54526 -2.36864 -0.65215 -2.60003</acceleration>
          <wrench>0.202591 -27.1077 -0.123312 0 -0 0</wrench>
        </link>
        <link name='r_wheel_link'>
          <pose frame=''>-0.061552 -0.328075 0.060099 -3.14157 1.00029 -1.55857</pose>
          <velocity>-5e-06 5.6e-05 -0.001149 -0.000929 -8.6e-05 -5e-06</velocity>
          <acceleration>-0.014146 0.088947 -2.97782 -1.49488 -0.27553 -0.011378</acceleration>
          <wrench>-0.061595 0.387291 -12.966 0 -0 0</wrench>
        </link>
        <link name='shoulder_lift_link'>
          <pose frame=''>-0.366111 -0.292148 1.15072 -0 0.000101 3.08295</pose>
          <velocity>-0.000131 -0.000343 -0.009631 0.001067 0.033939 0.0123</velocity>
          <acceleration>-0.362706 -4.52331 5.25186 0.905981 -1.13355 -1.36398</acceleration>
          <wrench>-0.965343 -12.0388 13.9778 0 -0 0</wrench>
        </link>
        <link name='shoulder_pan_link'>
          <pose frame=''>-0.249311 -0.299005 1.09072 0 1e-05 3.08295</pose>
          <velocity>-5.5e-05 0.001038 -0.009606 -0.000942 -0.000188 0.012186</velocity>
          <acceleration>-0.474092 -0.453535 9.71947 -1.05267 0.995497 1.83844</acceleration>
          <wrench>-1.21306 -1.16046 24.8692 0 -0 0</wrench>
        </link>
        <link name='torso_lift_link'>
          <pose frame=''>-0.247848 -0.418521 0.74214 -1e-05 1e-06 1.583</pose>
          <velocity>-6.7e-05 0.000702 -0.009555 -0.000951 -4.4e-05 4.5e-05</velocity>
          <acceleration>-0.231717 1.56346 9.83414 -1.91349 0.285188 -0.287871</acceleration>
          <wrench>-2.53707 17.1183 107.674 0 -0 0</wrench>
        </link>
        <link name='upperarm_roll_link'>
          <pose frame=''>-0.584734 -0.279313 1.1507 -3.2e-05 0.000101 3.08295</pose>
          <velocity>-0.000276 -0.003117 -0.0022 -0.012262 0.034705 0.012191</velocity>
          <acceleration>-0.748538 -9.28684 -0.740183 -0.75462 1.44561 1.94095</acceleration>
          <wrench>-1.74492 -21.6486 -1.72544 0 -0 0</wrench>
        </link>
        <link name='wrist_flex_link'>
          <pose frame=''>-0.717776 -0.271513 1.47218 3.09806 -1.56995 3.12212</pose>
          <velocity>0.016116 -0.001915 0.002225 -0.011781 -0.029123 -1.97765</velocity>
          <acceleration>33.1766 -2.00446 -1.49914 0.213604 -0.453861 2.93944</acceleration>
          <wrench>57.2296 -3.45769 -2.58601 0 -0 0</wrench>
        </link>
        <link name='wrist_roll_link'>
          <pose frame=''>-0.717893 -0.271511 1.61068 3.09569 -1.56995 3.12244</pose>
          <velocity>0.013492 -0.000758 0.002185 -0.010929 -0.030425 0.002777</velocity>
          <acceleration>26.3407 0.088267 -1.48058 1.80555 1.37486 0.113693</acceleration>
          <wrench>43.5385 0.145896 -2.44725 0 -0 0</wrench>
        </link>
      </model>
      <model name='fetchit_arena1'>
        <pose frame=''>0 0 0 0 -0 0</pose>
        <scale>1 1 1</scale>
        <link name='link'>
          <pose frame=''>0 0 0 0 -0 0</pose>
          <velocity>0 0 0 0 -0 0</velocity>
          <acceleration>0 0 0 0 -0 0</acceleration>
          <wrench>0 0 0 0 -0 0</wrench>
        </link>
      </model>
      <model name='fetchit_table_sick1'>
        <pose frame=''>-0.305 1.28179 0 0 -0 0</pose>
        <scale>1 1 1</scale>
        <link name='link'>
          <pose frame=''>-0.305 1.28179 0 0 -0 0</pose>
          <velocity>0 0 0 0 -0 0</velocity>
          <acceleration>0 0 0 0 -0 0</acceleration>
          <wrench>0 0 0 0 -0 0</wrench>
        </link>
      </model>
      <model name='gearbox_bolt_grey12_clone'>
        <pose frame=''>-0.185871 1.20917 0.80149 1.72938 -0.582554 1.35964</pose>
        <scale>1 1 1</scale>
        <link name='link'>
          <pose frame=''>-0.185871 1.20917 0.80149 1.72938 -0.582554 1.35964</pose>
          <velocity>0.000117 -1.3e-05 8.6e-05 0.000813 0.007101 0</velocity>
          <acceleration>0 0 -9.8 0 -0 1e-06</acceleration>
          <wrench>0 0 -0.580998 0 -0 0</wrench>
        </link>
      </model>
      <model name='gearbox_bolt_grey5_clone'>
        <pose frame=''>-0.273053 1.14478 0.801483 -1.70555 -0.194336 0.036918</pose>
        <scale>1 1 1</scale>
        <link name='link'>
          <pose frame=''>-0.273053 1.14478 0.801483 -1.70555 -0.194336 0.036918</pose>
          <velocity>-4e-05 0.002969 0.011866 -0.180179 -0.002407 0</velocity>
          <acceleration>-0.058972 4.48453 12.7882 -2.1787 0.179957 0.141975</acceleration>
          <wrench>-0.003496 0.265868 0.758155 0 -0 0</wrench>
        </link>
      </model>
      <model name='gearbox_bottom_grey2'>
        <pose frame=''>0.010828 1.37377 0.804969 -1.5708 0 -2.98083</pose>
        <scale>1 1 1</scale>
        <link name='link'>
          <pose frame=''>0.010828 1.37377 0.804969 -1.5708 0 -2.98083</pose>
          <velocity>-0.00169 -0.000274 0.005008 0.013726 -0.084644 2e-06</velocity>
          <acceleration>-5.28987 -0.95465 5.9761 -0.80226 -0.296253 -1.05119</acceleration>
          <wrench>-1.96022 -0.353756 2.21451 0 -0 0</wrench>
        </link>
      </model>
      <model name='gearbox_bottom_grey3_clone'>
        <pose frame=''>-0.452791 1.16231 0.837368 3.14152 -5e-05 -2.40869</pose>
        <scale>1 1 1</scale>
        <link name='link'>
          <pose frame=''>-0.452791 1.16231 0.837368 3.14152 -5e-05 -2.40869</pose>
          <velocity>0.004531 0.004676 0.000103 -0.103765 0.069251 -0.022352</velocity>
          <acceleration>2.66779 5.17061 2.97581 -0.931705 1.02866 1.74739</acceleration>
          <wrench>0.988578 1.91603 1.10272 0 -0 0</wrench>
        </link>
      </model>
      <model name='gearbox_top_grey1'>
        <pose frame=''>-0.534774 1.28695 0.801285 -4.5e-05 0.173589 1.08885</pose>
        <scale>1 1 1</scale>
        <link name='link'>
          <pose frame=''>-0.534774 1.28695 0.801285 -4.5e-05 0.173589 1.08885</pose>
          <velocity>-0.00053 -0.001021 0.003333 0.06267 -0.03256 -1e-06</velocity>
          <acceleration>-1.0638 -2.03927 6.66554 1.47723 1.18506 0.101213</acceleration>
          <wrench>-0.242821 -0.465481 1.52147 0 -0 0</wrench>
        </link>
      </model>
      <model name='gearbox_top_grey2_clone'>
        <pose frame=''>-0.256631 1.34307 0.796855 3.14157 1e-06 0.087548</pose>
        <scale>1 1 1</scale>
        <link name='link'>
          <pose frame=''>-0.256631 1.34307 0.796855 3.14157 1e-06 0.087548</pose>
          <velocity>0.000345 0.000228 0.002235 -0.019263 0.029138 0</velocity>
          <acceleration>0.712912 0.372863 4.39526 0.326293 -0.020987 -1.01783</acceleration>
          <wrench>0.162729 0.085109 1.00326 0 -0 0</wrench>
        </link>
      </model>
      <model name='ground_plane'>
        <pose frame=''>0 0 -0.005 0 -0 0</pose>
        <scale>1 1 1</scale>
        <link name='link'>
          <pose frame=''>0 0 -0.005 0 -0 0</pose>
          <velocity>0 0 0 0 -0 0</velocity>
          <acceleration>0 0 0 0 -0 0</acceleration>
          <wrench>0 0 0 0 -0 0</wrench>
        </link>
      </model>
      <model name='large_gear_1_clone'>
        <pose frame=''>-0.41088 1.28248 0.820234 -1.82929 -0.625914 -1.43968</pose>
        <scale>1 1 1</scale>
        <link name='link'>
          <pose frame=''>-0.41088 1.28248 0.820234 -1.82929 -0.625914 -1.43968</pose>
          <velocity>0 0 0 0 -0 0</velocity>
          <acceleration>0 0 -9.8 2.5e-05 1e-06 0.000116</acceleration>
          <wrench>0 0 -2.33263 0 -0 0</wrench>
        </link>
      </model>
      <model name='large_gear_3_clone'>
        <pose frame=''>0.058619 1.18897 0.820215 2.05021 -1.10704 -1.69582</pose>
        <scale>1 1 1</scale>
        <link name='link'>
          <pose frame=''>0.058619 1.18897 0.820215 2.05021 -1.10704 -1.69582</pose>
          <velocity>0.002243 0.000577 -0.010424 -0.016908 0.063516 -0.000209</velocity>
          <acceleration>0 0 -9.8 4.5e-05 1.1e-05 -0.000218</acceleration>
          <wrench>0 0 -2.33263 0 -0 0</wrench>
        </link>
      </model>
      <model name='small_gear_2_clone'>
        <pose frame=''>-0.110753 1.26211 0.807251 -2.60582 -1.19924 -0.026971</pose>
        <scale>1 1 1</scale>
        <link name='link'>
          <pose frame=''>-0.110753 1.26211 0.807251 -2.60582 -1.19924 -0.026971</pose>
          <velocity>0.000377 0.00016 0.006363 -0.009772 0.015528 0.004566</velocity>
          <acceleration>3.44411 2.17598 10.4594 -2.06492 -0.426356 1.9606</acceleration>
          <wrench>0.197044 0.124492 0.598403 0 -0 0</wrench>
        </link>
      </model>
      <model name='small_gear_3_clone'>
        <pose frame=''>-0.622865 1.15712 0.807252 1.89429 -0.186405 -0.043874</pose>
        <scale>1 1 1</scale>
        <link name='link'>
          <pose frame=''>-0.622865 1.15712 0.807252 1.89429 -0.186405 -0.043874</pose>
          <velocity>0 0 0 0 -0 0</velocity>
          <acceleration>0 0 -9.8 0 0 -1e-06</acceleration>
          <wrench>0 0 -0.560676 0 -0 0</wrench>
        </link>
      </model>
      <light name='user_point_light_0'>
        <pose frame=''>1 1 3.5 0 -0 0</pose>
      </light>
      <light name='user_point_light_1'>
        <pose frame=''>-1 1 3.5 0 -0 0</pose>
      </light>
      <light name='user_point_light_2'>
        <pose frame=''>-1 -1 3.5 0 -0 0</pose>
      </light>
      <light name='user_point_light_3'>
        <pose frame=''>1 -1 3.5 0 -0 0</pose>
      </light>
    </state>
    <gui fullscreen='0'>
      <camera name='user_camera'>
        <pose frame=''>2.46528 -2.01445 4.15364 0 0.901805 2.809</pose>
        <view_controller>orbit</view_controller>
        <projection_type>perspective</projection_type>
      </camera>
    </gui>
  </world>
</sdf>
